[2024-11-20T15:51:40.663+0000] {local_task_job_runner.py:123} INFO - ::group::Pre task execution logs
[2024-11-20T15:51:40.684+0000] {taskinstance.py:2613} INFO - Dependencies all met for dep_context=non-requeueable deps ti=<TaskInstance: etl_pipeline.load_to_postgres manual__2024-11-20T15:47:36.829271+00:00 [queued]>
[2024-11-20T15:51:40.693+0000] {taskinstance.py:2613} INFO - Dependencies all met for dep_context=requeueable deps ti=<TaskInstance: etl_pipeline.load_to_postgres manual__2024-11-20T15:47:36.829271+00:00 [queued]>
[2024-11-20T15:51:40.696+0000] {taskinstance.py:2866} INFO - Starting attempt 2 of 2
[2024-11-20T15:51:40.712+0000] {taskinstance.py:2889} INFO - Executing <Task(PythonOperator): load_to_postgres> on 2024-11-20 15:47:36.829271+00:00
[2024-11-20T15:51:40.721+0000] {warnings.py:112} WARNING - /home/***/.local/lib/python3.12/site-packages/***/task/task_runner/standard_task_runner.py:70: DeprecationWarning: This process (pid=464) is multi-threaded, use of fork() may lead to deadlocks in the child.
  pid = os.fork()

[2024-11-20T15:51:40.723+0000] {standard_task_runner.py:72} INFO - Started process 466 to run task
[2024-11-20T15:51:40.723+0000] {standard_task_runner.py:104} INFO - Running: ['***', 'tasks', 'run', 'etl_pipeline', 'load_to_postgres', 'manual__2024-11-20T15:47:36.829271+00:00', '--job-id', '24', '--raw', '--subdir', 'DAGS_FOLDER/dag.py', '--cfg-path', '/tmp/tmpw8_5kdbr']
[2024-11-20T15:51:40.724+0000] {standard_task_runner.py:105} INFO - Job 24: Subtask load_to_postgres
[2024-11-20T15:51:40.766+0000] {task_command.py:467} INFO - Running <TaskInstance: etl_pipeline.load_to_postgres manual__2024-11-20T15:47:36.829271+00:00 [running]> on host 5fadb8d48c54
[2024-11-20T15:51:41.029+0000] {taskinstance.py:3132} INFO - Exporting env vars: AIRFLOW_CTX_DAG_OWNER='***' AIRFLOW_CTX_DAG_ID='etl_pipeline' AIRFLOW_CTX_TASK_ID='load_to_postgres' AIRFLOW_CTX_EXECUTION_DATE='2024-11-20T15:47:36.829271+00:00' AIRFLOW_CTX_TRY_NUMBER='2' AIRFLOW_CTX_DAG_RUN_ID='manual__2024-11-20T15:47:36.829271+00:00'
[2024-11-20T15:51:41.031+0000] {logging_mixin.py:190} INFO - Task instance is in running state
[2024-11-20T15:51:41.032+0000] {logging_mixin.py:190} INFO -  Previous state of the Task instance: queued
[2024-11-20T15:51:41.033+0000] {logging_mixin.py:190} INFO - Current task name:load_to_postgres state:running start_date:2024-11-20 15:51:40.684776+00:00
[2024-11-20T15:51:41.034+0000] {logging_mixin.py:190} INFO - Dag name:etl_pipeline and current dag run status:running
[2024-11-20T15:51:41.034+0000] {taskinstance.py:731} INFO - ::endgroup::
[2024-11-20T15:51:41.044+0000] {taskinstance.py:3311} ERROR - Task failed with exception
Traceback (most recent call last):
  File "/home/airflow/.local/lib/python3.12/site-packages/airflow/models/taskinstance.py", line 767, in _execute_task
    result = _execute_callable(context=context, **execute_callable_kwargs)
             ^^^^^^^^^^^^^^^^^^^^^^^^^^^^^^^^^^^^^^^^^^^^^^^^^^^^^^^^^^^^^
  File "/home/airflow/.local/lib/python3.12/site-packages/airflow/models/taskinstance.py", line 733, in _execute_callable
    return ExecutionCallableRunner(
           ^^^^^^^^^^^^^^^^^^^^^^^^
  File "/home/airflow/.local/lib/python3.12/site-packages/airflow/utils/operator_helpers.py", line 252, in run
    return self.func(*args, **kwargs)
           ^^^^^^^^^^^^^^^^^^^^^^^^^^
  File "/home/airflow/.local/lib/python3.12/site-packages/airflow/models/baseoperator.py", line 417, in wrapper
    return func(self, *args, **kwargs)
           ^^^^^^^^^^^^^^^^^^^^^^^^^^^
  File "/home/airflow/.local/lib/python3.12/site-packages/airflow/operators/python.py", line 238, in execute
    return_value = self.execute_callable()
                   ^^^^^^^^^^^^^^^^^^^^^^^
  File "/home/airflow/.local/lib/python3.12/site-packages/airflow/operators/python.py", line 256, in execute_callable
    return runner.run(*self.op_args, **self.op_kwargs)
           ^^^^^^^^^^^^^^^^^^^^^^^^^^^^^^^^^^^^^^^^^^^
  File "/home/airflow/.local/lib/python3.12/site-packages/airflow/utils/operator_helpers.py", line 252, in run
    return self.func(*args, **kwargs)
           ^^^^^^^^^^^^^^^^^^^^^^^^^^
  File "/opt/airflow/dags/etl/load.py", line 9, in insert_female_daily_data_into_postgres
    raise ValueError("No transformed data found")
ValueError: No transformed data found
[2024-11-20T15:51:41.071+0000] {logging_mixin.py:190} INFO - Task instance in failure state
[2024-11-20T15:51:41.072+0000] {logging_mixin.py:190} INFO - Task start:2024-11-20 15:51:40.684776+00:00 end:2024-11-20 15:51:41.070958+00:00 duration:0.386182
[2024-11-20T15:51:41.073+0000] {logging_mixin.py:190} INFO - Task:<Task(PythonOperator): load_to_postgres> dag:<DAG: etl_pipeline> dagrun:<DagRun etl_pipeline @ 2024-11-20 15:47:36.829271+00:00: manual__2024-11-20T15:47:36.829271+00:00, state:running, queued_at: 2024-11-20 15:51:31.242335+00:00. externally triggered: True>
[2024-11-20T15:51:41.074+0000] {logging_mixin.py:190} INFO - Failure caused by No transformed data found
[2024-11-20T15:51:41.075+0000] {taskinstance.py:1225} INFO - Marking task as FAILED. dag_id=etl_pipeline, task_id=load_to_postgres, run_id=manual__2024-11-20T15:47:36.829271+00:00, execution_date=20241120T154736, start_date=20241120T155140, end_date=20241120T155141
[2024-11-20T15:51:41.090+0000] {taskinstance.py:340} INFO - ::group::Post task execution logs
[2024-11-20T15:51:41.091+0000] {standard_task_runner.py:124} ERROR - Failed to execute job 24 for task load_to_postgres (No transformed data found; 466)
Traceback (most recent call last):
  File "/home/airflow/.local/lib/python3.12/site-packages/airflow/task/task_runner/standard_task_runner.py", line 117, in _start_by_fork
    ret = args.func(args, dag=self.dag)
          ^^^^^^^^^^^^^^^^^^^^^^^^^^^^^
  File "/home/airflow/.local/lib/python3.12/site-packages/airflow/cli/cli_config.py", line 49, in command
    return func(*args, **kwargs)
           ^^^^^^^^^^^^^^^^^^^^^
  File "/home/airflow/.local/lib/python3.12/site-packages/airflow/utils/cli.py", line 116, in wrapper
    return f(*args, **kwargs)
           ^^^^^^^^^^^^^^^^^^
  File "/home/airflow/.local/lib/python3.12/site-packages/airflow/cli/commands/task_command.py", line 483, in task_run
    task_return_code = _run_task_by_selected_method(args, _dag, ti)
                       ^^^^^^^^^^^^^^^^^^^^^^^^^^^^^^^^^^^^^^^^^^^^
  File "/home/airflow/.local/lib/python3.12/site-packages/airflow/cli/commands/task_command.py", line 256, in _run_task_by_selected_method
    return _run_raw_task(args, ti)
           ^^^^^^^^^^^^^^^^^^^^^^^
  File "/home/airflow/.local/lib/python3.12/site-packages/airflow/cli/commands/task_command.py", line 341, in _run_raw_task
    return ti._run_raw_task(
           ^^^^^^^^^^^^^^^^^
  File "/home/airflow/.local/lib/python3.12/site-packages/airflow/utils/session.py", line 97, in wrapper
    return func(*args, session=session, **kwargs)
           ^^^^^^^^^^^^^^^^^^^^^^^^^^^^^^^^^^^^^^
  File "/home/airflow/.local/lib/python3.12/site-packages/airflow/models/taskinstance.py", line 3005, in _run_raw_task
    return _run_raw_task(
           ^^^^^^^^^^^^^^
  File "/home/airflow/.local/lib/python3.12/site-packages/airflow/models/taskinstance.py", line 273, in _run_raw_task
    TaskInstance._execute_task_with_callbacks(
  File "/home/airflow/.local/lib/python3.12/site-packages/airflow/models/taskinstance.py", line 3159, in _execute_task_with_callbacks
    result = self._execute_task(context, task_orig)
             ^^^^^^^^^^^^^^^^^^^^^^^^^^^^^^^^^^^^^^
  File "/home/airflow/.local/lib/python3.12/site-packages/airflow/models/taskinstance.py", line 3183, in _execute_task
    return _execute_task(self, context, task_orig)
           ^^^^^^^^^^^^^^^^^^^^^^^^^^^^^^^^^^^^^^^
  File "/home/airflow/.local/lib/python3.12/site-packages/airflow/models/taskinstance.py", line 767, in _execute_task
    result = _execute_callable(context=context, **execute_callable_kwargs)
             ^^^^^^^^^^^^^^^^^^^^^^^^^^^^^^^^^^^^^^^^^^^^^^^^^^^^^^^^^^^^^
  File "/home/airflow/.local/lib/python3.12/site-packages/airflow/models/taskinstance.py", line 733, in _execute_callable
    return ExecutionCallableRunner(
           ^^^^^^^^^^^^^^^^^^^^^^^^
  File "/home/airflow/.local/lib/python3.12/site-packages/airflow/utils/operator_helpers.py", line 252, in run
    return self.func(*args, **kwargs)
           ^^^^^^^^^^^^^^^^^^^^^^^^^^
  File "/home/airflow/.local/lib/python3.12/site-packages/airflow/models/baseoperator.py", line 417, in wrapper
    return func(self, *args, **kwargs)
           ^^^^^^^^^^^^^^^^^^^^^^^^^^^
  File "/home/airflow/.local/lib/python3.12/site-packages/airflow/operators/python.py", line 238, in execute
    return_value = self.execute_callable()
                   ^^^^^^^^^^^^^^^^^^^^^^^
  File "/home/airflow/.local/lib/python3.12/site-packages/airflow/operators/python.py", line 256, in execute_callable
    return runner.run(*self.op_args, **self.op_kwargs)
           ^^^^^^^^^^^^^^^^^^^^^^^^^^^^^^^^^^^^^^^^^^^
  File "/home/airflow/.local/lib/python3.12/site-packages/airflow/utils/operator_helpers.py", line 252, in run
    return self.func(*args, **kwargs)
           ^^^^^^^^^^^^^^^^^^^^^^^^^^
  File "/opt/airflow/dags/etl/load.py", line 9, in insert_female_daily_data_into_postgres
    raise ValueError("No transformed data found")
ValueError: No transformed data found
[2024-11-20T15:51:41.139+0000] {local_task_job_runner.py:266} INFO - Task exited with return code 1
[2024-11-20T15:51:41.153+0000] {taskinstance.py:3895} INFO - 0 downstream tasks scheduled from follow-on schedule check
[2024-11-20T15:51:41.158+0000] {local_task_job_runner.py:245} INFO - ::endgroup::
