[2024-11-21T12:29:01.353+0000] {local_task_job_runner.py:123} INFO - ::group::Pre task execution logs
[2024-11-21T12:29:01.366+0000] {taskinstance.py:2613} INFO - Dependencies all met for dep_context=non-requeueable deps ti=<TaskInstance: etl_pipeline.create_table_azarine manual__2024-11-21T12:28:43.371314+00:00 [queued]>
[2024-11-21T12:29:01.374+0000] {taskinstance.py:2613} INFO - Dependencies all met for dep_context=requeueable deps ti=<TaskInstance: etl_pipeline.create_table_azarine manual__2024-11-21T12:28:43.371314+00:00 [queued]>
[2024-11-21T12:29:01.376+0000] {taskinstance.py:2866} INFO - Starting attempt 1 of 1
[2024-11-21T12:29:01.388+0000] {taskinstance.py:2889} INFO - Executing <Task(PostgresOperator): create_table_azarine> on 2024-11-21 12:28:43.371314+00:00
[2024-11-21T12:29:01.399+0000] {warnings.py:112} WARNING - /home/***/.local/lib/python3.12/site-packages/***/task/task_runner/standard_task_runner.py:70: DeprecationWarning: This process (pid=4715) is multi-threaded, use of fork() may lead to deadlocks in the child.
  pid = os.fork()

[2024-11-21T12:29:01.401+0000] {standard_task_runner.py:72} INFO - Started process 4717 to run task
[2024-11-21T12:29:01.401+0000] {standard_task_runner.py:104} INFO - Running: ['***', 'tasks', 'run', 'etl_pipeline', 'create_table_azarine', 'manual__2024-11-21T12:28:43.371314+00:00', '--job-id', '268', '--raw', '--subdir', 'DAGS_FOLDER/dag.py', '--cfg-path', '/tmp/tmpdxh18m3d']
[2024-11-21T12:29:01.402+0000] {standard_task_runner.py:105} INFO - Job 268: Subtask create_table_azarine
[2024-11-21T12:29:01.448+0000] {task_command.py:467} INFO - Running <TaskInstance: etl_pipeline.create_table_azarine manual__2024-11-21T12:28:43.371314+00:00 [running]> on host 7a40aa914b11
[2024-11-21T12:29:01.689+0000] {taskinstance.py:3132} INFO - Exporting env vars: AIRFLOW_CTX_DAG_OWNER='***' AIRFLOW_CTX_DAG_ID='etl_pipeline' AIRFLOW_CTX_TASK_ID='create_table_azarine' AIRFLOW_CTX_EXECUTION_DATE='2024-11-21T12:28:43.371314+00:00' AIRFLOW_CTX_TRY_NUMBER='1' AIRFLOW_CTX_DAG_RUN_ID='manual__2024-11-21T12:28:43.371314+00:00'
[2024-11-21T12:29:01.691+0000] {logging_mixin.py:190} INFO - Task instance is in running state
[2024-11-21T12:29:01.691+0000] {logging_mixin.py:190} INFO -  Previous state of the Task instance: queued
[2024-11-21T12:29:01.692+0000] {logging_mixin.py:190} INFO - Current task name:create_table_azarine state:running start_date:2024-11-21 12:29:01.368203+00:00
[2024-11-21T12:29:01.693+0000] {logging_mixin.py:190} INFO - Dag name:etl_pipeline and current dag run status:running
[2024-11-21T12:29:01.694+0000] {taskinstance.py:731} INFO - ::endgroup::
[2024-11-21T12:29:01.696+0000] {sql.py:278} INFO - Executing: 
        CREATE TABLE IF NOT EXISTS skincare_azarine (
            id SERIAL PRIMARY KEY,
            username TEXT NOT NULL,
            date TIMESTAMP,
            review_content TEXT,
            purchase_point TEXT,
            recommend TEXT,
            rating INTEGER,
            jenis_produk TEXT,
            trend INTEGER,
            age_category TEXT,
            periode_penggunaan TEXT,
            skintype TEXT,
            skintone TEXT,
            undertone TEXT,
            tren INTEGER,
        );
    
[2024-11-21T12:29:01.707+0000] {base.py:84} INFO - Retrieving connection 'skincare_connection'
[2024-11-21T12:29:01.714+0000] {base.py:84} INFO - Retrieving connection 'skincare_connection'
[2024-11-21T12:29:01.721+0000] {sql.py:544} INFO - Running statement: 
        CREATE TABLE IF NOT EXISTS skincare_azarine (
            id SERIAL PRIMARY KEY,
            username TEXT NOT NULL,
            date TIMESTAMP,
            review_content TEXT,
            purchase_point TEXT,
            recommend TEXT,
            rating INTEGER,
            jenis_produk TEXT,
            trend INTEGER,
            age_category TEXT,
            periode_penggunaan TEXT,
            skintype TEXT,
            skintone TEXT,
            undertone TEXT,
            tren INTEGER,
        );
    , parameters: None
[2024-11-21T12:29:01.733+0000] {taskinstance.py:3311} ERROR - Task failed with exception
Traceback (most recent call last):
  File "/home/airflow/.local/lib/python3.12/site-packages/airflow/models/taskinstance.py", line 767, in _execute_task
    result = _execute_callable(context=context, **execute_callable_kwargs)
             ^^^^^^^^^^^^^^^^^^^^^^^^^^^^^^^^^^^^^^^^^^^^^^^^^^^^^^^^^^^^^
  File "/home/airflow/.local/lib/python3.12/site-packages/airflow/models/taskinstance.py", line 733, in _execute_callable
    return ExecutionCallableRunner(
           ^^^^^^^^^^^^^^^^^^^^^^^^
  File "/home/airflow/.local/lib/python3.12/site-packages/airflow/utils/operator_helpers.py", line 252, in run
    return self.func(*args, **kwargs)
           ^^^^^^^^^^^^^^^^^^^^^^^^^^
  File "/home/airflow/.local/lib/python3.12/site-packages/airflow/models/baseoperator.py", line 417, in wrapper
    return func(self, *args, **kwargs)
           ^^^^^^^^^^^^^^^^^^^^^^^^^^^
  File "/home/airflow/.local/lib/python3.12/site-packages/airflow/providers/common/sql/operators/sql.py", line 284, in execute
    output = hook.run(
             ^^^^^^^^^
  File "/home/airflow/.local/lib/python3.12/site-packages/airflow/providers/common/sql/hooks/sql.py", line 489, in run
    self._run_command(cur, sql_statement, parameters)
  File "/home/airflow/.local/lib/python3.12/site-packages/airflow/providers/common/sql/hooks/sql.py", line 549, in _run_command
    cur.execute(sql_statement)
psycopg2.errors.SyntaxError: syntax error at or near ")"
LINE 18:         );
                 ^

[2024-11-21T12:29:01.743+0000] {logging_mixin.py:190} INFO - Task instance in failure state
[2024-11-21T12:29:01.744+0000] {logging_mixin.py:190} INFO - Task start:2024-11-21 12:29:01.368203+00:00 end:2024-11-21 12:29:01.743549+00:00 duration:0.375346
[2024-11-21T12:29:01.745+0000] {logging_mixin.py:190} INFO - Task:<Task(PostgresOperator): create_table_azarine> dag:<DAG: etl_pipeline> dagrun:<DagRun etl_pipeline @ 2024-11-21 12:28:43.371314+00:00: manual__2024-11-21T12:28:43.371314+00:00, state:running, queued_at: 2024-11-21 12:28:43.500846+00:00. externally triggered: True>
[2024-11-21T12:29:01.746+0000] {logging_mixin.py:190} INFO - Failure caused by syntax error at or near ")"
LINE 18:         );
                 ^
[2024-11-21T12:29:01.747+0000] {taskinstance.py:1225} INFO - Marking task as FAILED. dag_id=etl_pipeline, task_id=create_table_azarine, run_id=manual__2024-11-21T12:28:43.371314+00:00, execution_date=20241121T122843, start_date=20241121T122901, end_date=20241121T122901
[2024-11-21T12:29:01.760+0000] {taskinstance.py:340} INFO - ::group::Post task execution logs
[2024-11-21T12:29:01.761+0000] {standard_task_runner.py:124} ERROR - Failed to execute job 268 for task create_table_azarine (syntax error at or near ")"
LINE 18:         );
                 ^
; 4717)
Traceback (most recent call last):
  File "/home/airflow/.local/lib/python3.12/site-packages/airflow/task/task_runner/standard_task_runner.py", line 117, in _start_by_fork
    ret = args.func(args, dag=self.dag)
          ^^^^^^^^^^^^^^^^^^^^^^^^^^^^^
  File "/home/airflow/.local/lib/python3.12/site-packages/airflow/cli/cli_config.py", line 49, in command
    return func(*args, **kwargs)
           ^^^^^^^^^^^^^^^^^^^^^
  File "/home/airflow/.local/lib/python3.12/site-packages/airflow/utils/cli.py", line 116, in wrapper
    return f(*args, **kwargs)
           ^^^^^^^^^^^^^^^^^^
  File "/home/airflow/.local/lib/python3.12/site-packages/airflow/cli/commands/task_command.py", line 483, in task_run
    task_return_code = _run_task_by_selected_method(args, _dag, ti)
                       ^^^^^^^^^^^^^^^^^^^^^^^^^^^^^^^^^^^^^^^^^^^^
  File "/home/airflow/.local/lib/python3.12/site-packages/airflow/cli/commands/task_command.py", line 256, in _run_task_by_selected_method
    return _run_raw_task(args, ti)
           ^^^^^^^^^^^^^^^^^^^^^^^
  File "/home/airflow/.local/lib/python3.12/site-packages/airflow/cli/commands/task_command.py", line 341, in _run_raw_task
    return ti._run_raw_task(
           ^^^^^^^^^^^^^^^^^
  File "/home/airflow/.local/lib/python3.12/site-packages/airflow/utils/session.py", line 97, in wrapper
    return func(*args, session=session, **kwargs)
           ^^^^^^^^^^^^^^^^^^^^^^^^^^^^^^^^^^^^^^
  File "/home/airflow/.local/lib/python3.12/site-packages/airflow/models/taskinstance.py", line 3005, in _run_raw_task
    return _run_raw_task(
           ^^^^^^^^^^^^^^
  File "/home/airflow/.local/lib/python3.12/site-packages/airflow/models/taskinstance.py", line 273, in _run_raw_task
    TaskInstance._execute_task_with_callbacks(
  File "/home/airflow/.local/lib/python3.12/site-packages/airflow/models/taskinstance.py", line 3159, in _execute_task_with_callbacks
    result = self._execute_task(context, task_orig)
             ^^^^^^^^^^^^^^^^^^^^^^^^^^^^^^^^^^^^^^
  File "/home/airflow/.local/lib/python3.12/site-packages/airflow/models/taskinstance.py", line 3183, in _execute_task
    return _execute_task(self, context, task_orig)
           ^^^^^^^^^^^^^^^^^^^^^^^^^^^^^^^^^^^^^^^
  File "/home/airflow/.local/lib/python3.12/site-packages/airflow/models/taskinstance.py", line 767, in _execute_task
    result = _execute_callable(context=context, **execute_callable_kwargs)
             ^^^^^^^^^^^^^^^^^^^^^^^^^^^^^^^^^^^^^^^^^^^^^^^^^^^^^^^^^^^^^
  File "/home/airflow/.local/lib/python3.12/site-packages/airflow/models/taskinstance.py", line 733, in _execute_callable
    return ExecutionCallableRunner(
           ^^^^^^^^^^^^^^^^^^^^^^^^
  File "/home/airflow/.local/lib/python3.12/site-packages/airflow/utils/operator_helpers.py", line 252, in run
    return self.func(*args, **kwargs)
           ^^^^^^^^^^^^^^^^^^^^^^^^^^
  File "/home/airflow/.local/lib/python3.12/site-packages/airflow/models/baseoperator.py", line 417, in wrapper
    return func(self, *args, **kwargs)
           ^^^^^^^^^^^^^^^^^^^^^^^^^^^
  File "/home/airflow/.local/lib/python3.12/site-packages/airflow/providers/common/sql/operators/sql.py", line 284, in execute
    output = hook.run(
             ^^^^^^^^^
  File "/home/airflow/.local/lib/python3.12/site-packages/airflow/providers/common/sql/hooks/sql.py", line 489, in run
    self._run_command(cur, sql_statement, parameters)
  File "/home/airflow/.local/lib/python3.12/site-packages/airflow/providers/common/sql/hooks/sql.py", line 549, in _run_command
    cur.execute(sql_statement)
psycopg2.errors.SyntaxError: syntax error at or near ")"
LINE 18:         );
                 ^

[2024-11-21T12:29:01.778+0000] {local_task_job_runner.py:266} INFO - Task exited with return code 1
[2024-11-21T12:29:01.796+0000] {taskinstance.py:3895} INFO - 0 downstream tasks scheduled from follow-on schedule check
[2024-11-21T12:29:01.803+0000] {local_task_job_runner.py:245} INFO - ::endgroup::
