[2024-11-21T04:46:29.576+0000] {local_task_job_runner.py:123} INFO - ::group::Pre task execution logs
[2024-11-21T04:46:29.590+0000] {taskinstance.py:2613} INFO - Dependencies all met for dep_context=non-requeueable deps ti=<TaskInstance: etl_pipeline.extract_google_trends manual__2024-11-21T04:46:11.578349+00:00 [queued]>
[2024-11-21T04:46:29.598+0000] {taskinstance.py:2613} INFO - Dependencies all met for dep_context=requeueable deps ti=<TaskInstance: etl_pipeline.extract_google_trends manual__2024-11-21T04:46:11.578349+00:00 [queued]>
[2024-11-21T04:46:29.599+0000] {taskinstance.py:2866} INFO - Starting attempt 1 of 1
[2024-11-21T04:46:29.613+0000] {taskinstance.py:2889} INFO - Executing <Task(PythonOperator): extract_google_trends> on 2024-11-21 04:46:11.578349+00:00
[2024-11-21T04:46:29.622+0000] {warnings.py:112} WARNING - /home/***/.local/lib/python3.12/site-packages/***/task/task_runner/standard_task_runner.py:70: DeprecationWarning: This process (pid=547) is multi-threaded, use of fork() may lead to deadlocks in the child.
  pid = os.fork()

[2024-11-21T04:46:29.624+0000] {standard_task_runner.py:104} INFO - Running: ['***', 'tasks', 'run', 'etl_pipeline', 'extract_google_trends', 'manual__2024-11-21T04:46:11.578349+00:00', '--job-id', '108', '--raw', '--subdir', 'DAGS_FOLDER/dag.py', '--cfg-path', '/tmp/tmpia_z74yn']
[2024-11-21T04:46:29.625+0000] {standard_task_runner.py:72} INFO - Started process 556 to run task
[2024-11-21T04:46:29.625+0000] {standard_task_runner.py:105} INFO - Job 108: Subtask extract_google_trends
[2024-11-21T04:46:29.672+0000] {task_command.py:467} INFO - Running <TaskInstance: etl_pipeline.extract_google_trends manual__2024-11-21T04:46:11.578349+00:00 [running]> on host 03a340403ece
[2024-11-21T04:46:29.773+0000] {taskinstance.py:3132} INFO - Exporting env vars: AIRFLOW_CTX_DAG_OWNER='***' AIRFLOW_CTX_DAG_ID='etl_pipeline' AIRFLOW_CTX_TASK_ID='extract_google_trends' AIRFLOW_CTX_EXECUTION_DATE='2024-11-21T04:46:11.578349+00:00' AIRFLOW_CTX_TRY_NUMBER='1' AIRFLOW_CTX_DAG_RUN_ID='manual__2024-11-21T04:46:11.578349+00:00'
[2024-11-21T04:46:29.775+0000] {logging_mixin.py:190} INFO - Task instance is in running state
[2024-11-21T04:46:29.776+0000] {logging_mixin.py:190} INFO -  Previous state of the Task instance: queued
[2024-11-21T04:46:29.777+0000] {logging_mixin.py:190} INFO - Current task name:extract_google_trends state:running start_date:2024-11-21 04:46:29.591748+00:00
[2024-11-21T04:46:29.777+0000] {logging_mixin.py:190} INFO - Dag name:etl_pipeline and current dag run status:running
[2024-11-21T04:46:29.778+0000] {taskinstance.py:731} INFO - ::endgroup::
[2024-11-21T04:46:29.780+0000] {logging_mixin.py:190} INFO - Menjalankan Actor di Apify untuk 'sunscreen Azarine'...
[2024-11-21T04:46:29.781+0000] {logging_mixin.py:190} INFO - Menjalankan Actor di Apify untuk 'sunscreen Skin Aqua'...
[2024-11-21T04:46:31.314+0000] {logging_mixin.py:190} INFO - Actor dijalankan dengan run_id: 3ftX4As4D5eLVbnDA
[2024-11-21T04:46:31.314+0000] {logging_mixin.py:190} INFO - Actor dijalankan dengan run_id: WT24TjpvvnmjLjOhx
[2024-11-21T04:46:32.635+0000] {logging_mixin.py:190} INFO - Error checking status: 404 - {
  "error": {
    "type": "page-not-found",
    "message": "We have bad news: there is no API endpoint at this URL. Did you specify it correctly?"
  }
}
[2024-11-21T04:46:32.636+0000] {logging_mixin.py:190} INFO - Error checking status: 404 - {
  "error": {
    "type": "page-not-found",
    "message": "We have bad news: there is no API endpoint at this URL. Did you specify it correctly?"
  }
}
[2024-11-21T04:46:32.638+0000] {logging_mixin.py:190} INFO - Unknown status: None
[2024-11-21T04:46:32.638+0000] {logging_mixin.py:190} INFO - Unknown status: None
[2024-11-21T04:47:03.864+0000] {logging_mixin.py:190} INFO - Error checking status: 404 - {
  "error": {
    "type": "page-not-found",
    "message": "We have bad news: there is no API endpoint at this URL. Did you specify it correctly?"
  }
}
[2024-11-21T04:47:03.867+0000] {logging_mixin.py:190} INFO - Error checking status: 404 - {
  "error": {
    "type": "page-not-found",
    "message": "We have bad news: there is no API endpoint at this URL. Did you specify it correctly?"
  }
}
[2024-11-21T04:47:03.868+0000] {logging_mixin.py:190} INFO - Unknown status: None
[2024-11-21T04:47:03.869+0000] {logging_mixin.py:190} INFO - Unknown status: None
[2024-11-21T04:47:35.020+0000] {logging_mixin.py:190} INFO - Error checking status: 404 - {
  "error": {
    "type": "page-not-found",
    "message": "We have bad news: there is no API endpoint at this URL. Did you specify it correctly?"
  }
}
[2024-11-21T04:47:35.021+0000] {logging_mixin.py:190} INFO - Error checking status: 404 - {
  "error": {
    "type": "page-not-found",
    "message": "We have bad news: there is no API endpoint at this URL. Did you specify it correctly?"
  }
}
[2024-11-21T04:47:35.022+0000] {logging_mixin.py:190} INFO - Unknown status: None
[2024-11-21T04:47:35.022+0000] {logging_mixin.py:190} INFO - Unknown status: None
[2024-11-21T04:48:06.331+0000] {logging_mixin.py:190} INFO - Error checking status: 404 - {
  "error": {
    "type": "page-not-found",
    "message": "We have bad news: there is no API endpoint at this URL. Did you specify it correctly?"
  }
}
[2024-11-21T04:48:06.333+0000] {logging_mixin.py:190} INFO - Error checking status: 404 - {
  "error": {
    "type": "page-not-found",
    "message": "We have bad news: there is no API endpoint at this URL. Did you specify it correctly?"
  }
}
[2024-11-21T04:48:06.334+0000] {logging_mixin.py:190} INFO - Unknown status: None
[2024-11-21T04:48:06.336+0000] {logging_mixin.py:190} INFO - Unknown status: None
[2024-11-21T04:48:20.463+0000] {local_task_job_runner.py:346} WARNING - State of this instance has been externally set to restarting. Terminating instance.
[2024-11-21T04:48:20.465+0000] {local_task_job_runner.py:245} INFO - ::endgroup::
[2024-11-21T04:48:20.469+0000] {process_utils.py:132} INFO - Sending 15 to group 556. PIDs of all processes in the group: [556]
[2024-11-21T04:48:20.470+0000] {process_utils.py:87} INFO - Sending the signal 15 to group 556
[2024-11-21T04:48:20.472+0000] {taskinstance.py:3093} ERROR - Received SIGTERM. Terminating subprocesses.
[2024-11-21T04:48:20.483+0000] {taskinstance.py:3311} ERROR - Task failed with exception
Traceback (most recent call last):
  File "/home/airflow/.local/lib/python3.12/site-packages/airflow/models/taskinstance.py", line 767, in _execute_task
    result = _execute_callable(context=context, **execute_callable_kwargs)
             ^^^^^^^^^^^^^^^^^^^^^^^^^^^^^^^^^^^^^^^^^^^^^^^^^^^^^^^^^^^^^
  File "/home/airflow/.local/lib/python3.12/site-packages/airflow/models/taskinstance.py", line 733, in _execute_callable
    return ExecutionCallableRunner(
           ^^^^^^^^^^^^^^^^^^^^^^^^
  File "/home/airflow/.local/lib/python3.12/site-packages/airflow/utils/operator_helpers.py", line 252, in run
    return self.func(*args, **kwargs)
           ^^^^^^^^^^^^^^^^^^^^^^^^^^
  File "/home/airflow/.local/lib/python3.12/site-packages/airflow/models/baseoperator.py", line 417, in wrapper
    return func(self, *args, **kwargs)
           ^^^^^^^^^^^^^^^^^^^^^^^^^^^
  File "/home/airflow/.local/lib/python3.12/site-packages/airflow/operators/python.py", line 238, in execute
    return_value = self.execute_callable()
                   ^^^^^^^^^^^^^^^^^^^^^^^
  File "/home/airflow/.local/lib/python3.12/site-packages/airflow/operators/python.py", line 256, in execute_callable
    return runner.run(*self.op_args, **self.op_kwargs)
           ^^^^^^^^^^^^^^^^^^^^^^^^^^^^^^^^^^^^^^^^^^^
  File "/home/airflow/.local/lib/python3.12/site-packages/airflow/utils/operator_helpers.py", line 252, in run
    return self.func(*args, **kwargs)
           ^^^^^^^^^^^^^^^^^^^^^^^^^^
  File "/opt/airflow/dags/etl/extract_google_trends.py", line 118, in extract_google_trends
    with concurrent.futures.ThreadPoolExecutor() as executor:
         ^^^^^^^^^^^^^^^^^^^^^^^^^^^^^^^^^^^^^^^
  File "/usr/local/lib/python3.12/concurrent/futures/_base.py", line 647, in __exit__
    self.shutdown(wait=True)
  File "/usr/local/lib/python3.12/concurrent/futures/thread.py", line 238, in shutdown
    t.join()
  File "/usr/local/lib/python3.12/threading.py", line 1149, in join
    self._wait_for_tstate_lock()
  File "/usr/local/lib/python3.12/threading.py", line 1169, in _wait_for_tstate_lock
    if lock.acquire(block, timeout):
       ^^^^^^^^^^^^^^^^^^^^^^^^^^^^
  File "/home/airflow/.local/lib/python3.12/site-packages/airflow/models/taskinstance.py", line 3095, in signal_handler
    raise AirflowTaskTerminated("Task received SIGTERM signal")
airflow.exceptions.AirflowTaskTerminated: Task received SIGTERM signal
[2024-11-21T04:48:20.515+0000] {logging_mixin.py:190} INFO - Task instance in failure state
[2024-11-21T04:48:20.516+0000] {logging_mixin.py:190} INFO - Task start:2024-11-21 04:46:29.591748+00:00 end:2024-11-21 04:48:20.514861+00:00 duration:110.923113
[2024-11-21T04:48:20.517+0000] {logging_mixin.py:190} INFO - Task:<Task(PythonOperator): extract_google_trends> dag:<DAG: etl_pipeline> dagrun:<DagRun etl_pipeline @ 2024-11-21 04:46:11.578349+00:00: manual__2024-11-21T04:46:11.578349+00:00, state:running, queued_at: 2024-11-21 04:46:11.727250+00:00. externally triggered: True>
[2024-11-21T04:48:20.518+0000] {logging_mixin.py:190} INFO - Failure caused by Task received SIGTERM signal
[2024-11-21T04:48:20.519+0000] {taskinstance.py:1225} INFO - Marking task as UP_FOR_RETRY. dag_id=etl_pipeline, task_id=extract_google_trends, run_id=manual__2024-11-21T04:46:11.578349+00:00, execution_date=20241121T044611, start_date=20241121T044629, end_date=20241121T044820
[2024-11-21T04:48:20.538+0000] {taskinstance.py:340} INFO - ::group::Post task execution logs
[2024-11-21T04:48:20.564+0000] {process_utils.py:80} INFO - Process psutil.Process(pid=556, status='terminated', exitcode=2, started='04:46:29') (556) terminated with exit code 2
