[2024-11-21T07:17:41.776+0000] {local_task_job_runner.py:123} INFO - ::group::Pre task execution logs
[2024-11-21T07:17:41.791+0000] {taskinstance.py:2613} INFO - Dependencies all met for dep_context=non-requeueable deps ti=<TaskInstance: etl_pipeline.transform_google_trends manual__2024-11-21T07:17:25.563459+00:00 [queued]>
[2024-11-21T07:17:41.802+0000] {taskinstance.py:2613} INFO - Dependencies all met for dep_context=requeueable deps ti=<TaskInstance: etl_pipeline.transform_google_trends manual__2024-11-21T07:17:25.563459+00:00 [queued]>
[2024-11-21T07:17:41.804+0000] {taskinstance.py:2866} INFO - Starting attempt 1 of 1
[2024-11-21T07:17:41.818+0000] {taskinstance.py:2889} INFO - Executing <Task(PythonOperator): transform_google_trends> on 2024-11-21 07:17:25.563459+00:00
[2024-11-21T07:17:41.829+0000] {warnings.py:112} WARNING - /home/***/.local/lib/python3.12/site-packages/***/task/task_runner/standard_task_runner.py:70: DeprecationWarning: This process (pid=99) is multi-threaded, use of fork() may lead to deadlocks in the child.
  pid = os.fork()

[2024-11-21T07:17:41.831+0000] {standard_task_runner.py:72} INFO - Started process 101 to run task
[2024-11-21T07:17:41.831+0000] {standard_task_runner.py:104} INFO - Running: ['***', 'tasks', 'run', 'etl_pipeline', 'transform_google_trends', 'manual__2024-11-21T07:17:25.563459+00:00', '--job-id', '114', '--raw', '--subdir', 'DAGS_FOLDER/dag.py', '--cfg-path', '/tmp/tmpaimx9xnk']
[2024-11-21T07:17:41.833+0000] {standard_task_runner.py:105} INFO - Job 114: Subtask transform_google_trends
[2024-11-21T07:17:41.874+0000] {task_command.py:467} INFO - Running <TaskInstance: etl_pipeline.transform_google_trends manual__2024-11-21T07:17:25.563459+00:00 [running]> on host 7a40aa914b11
[2024-11-21T07:17:42.116+0000] {taskinstance.py:3132} INFO - Exporting env vars: AIRFLOW_CTX_DAG_OWNER='***' AIRFLOW_CTX_DAG_ID='etl_pipeline' AIRFLOW_CTX_TASK_ID='transform_google_trends' AIRFLOW_CTX_EXECUTION_DATE='2024-11-21T07:17:25.563459+00:00' AIRFLOW_CTX_TRY_NUMBER='1' AIRFLOW_CTX_DAG_RUN_ID='manual__2024-11-21T07:17:25.563459+00:00'
[2024-11-21T07:17:42.117+0000] {logging_mixin.py:190} INFO - Task instance is in running state
[2024-11-21T07:17:42.118+0000] {logging_mixin.py:190} INFO -  Previous state of the Task instance: queued
[2024-11-21T07:17:42.119+0000] {logging_mixin.py:190} INFO - Current task name:transform_google_trends state:running start_date:2024-11-21 07:17:41.792606+00:00
[2024-11-21T07:17:42.120+0000] {logging_mixin.py:190} INFO - Dag name:etl_pipeline and current dag run status:running
[2024-11-21T07:17:42.121+0000] {taskinstance.py:731} INFO - ::endgroup::
[2024-11-21T07:17:42.128+0000] {taskinstance.py:3311} ERROR - Task failed with exception
Traceback (most recent call last):
  File "/home/airflow/.local/lib/python3.12/site-packages/airflow/models/taskinstance.py", line 767, in _execute_task
    result = _execute_callable(context=context, **execute_callable_kwargs)
             ^^^^^^^^^^^^^^^^^^^^^^^^^^^^^^^^^^^^^^^^^^^^^^^^^^^^^^^^^^^^^
  File "/home/airflow/.local/lib/python3.12/site-packages/airflow/models/taskinstance.py", line 733, in _execute_callable
    return ExecutionCallableRunner(
           ^^^^^^^^^^^^^^^^^^^^^^^^
  File "/home/airflow/.local/lib/python3.12/site-packages/airflow/utils/operator_helpers.py", line 252, in run
    return self.func(*args, **kwargs)
           ^^^^^^^^^^^^^^^^^^^^^^^^^^
  File "/home/airflow/.local/lib/python3.12/site-packages/airflow/models/baseoperator.py", line 417, in wrapper
    return func(self, *args, **kwargs)
           ^^^^^^^^^^^^^^^^^^^^^^^^^^^
  File "/home/airflow/.local/lib/python3.12/site-packages/airflow/operators/python.py", line 238, in execute
    return_value = self.execute_callable()
                   ^^^^^^^^^^^^^^^^^^^^^^^
  File "/home/airflow/.local/lib/python3.12/site-packages/airflow/operators/python.py", line 256, in execute_callable
    return runner.run(*self.op_args, **self.op_kwargs)
           ^^^^^^^^^^^^^^^^^^^^^^^^^^^^^^^^^^^^^^^^^^^
  File "/home/airflow/.local/lib/python3.12/site-packages/airflow/utils/operator_helpers.py", line 252, in run
    return self.func(*args, **kwargs)
           ^^^^^^^^^^^^^^^^^^^^^^^^^^
  File "/opt/airflow/dags/etl/transform_google_trends.py", line 46, in process_all_files
    for file_name in os.listdir(DATA_FOLDER):
                     ^^^^^^^^^^^^^^^^^^^^^^^
FileNotFoundError: [Errno 2] No such file or directory: '/opt/airflow/dags/etl/dags/hasil data extract'
[2024-11-21T07:17:42.157+0000] {logging_mixin.py:190} INFO - Task instance in failure state
[2024-11-21T07:17:42.158+0000] {logging_mixin.py:190} INFO - Task start:2024-11-21 07:17:41.792606+00:00 end:2024-11-21 07:17:42.157043+00:00 duration:0.364437
[2024-11-21T07:17:42.159+0000] {logging_mixin.py:190} INFO - Task:<Task(PythonOperator): transform_google_trends> dag:<DAG: etl_pipeline> dagrun:<DagRun etl_pipeline @ 2024-11-21 07:17:25.563459+00:00: manual__2024-11-21T07:17:25.563459+00:00, state:running, queued_at: 2024-11-21 07:17:25.658607+00:00. externally triggered: True>
[2024-11-21T07:17:42.159+0000] {logging_mixin.py:190} INFO - Failure caused by [Errno 2] No such file or directory: '/opt/***/dags/etl/dags/hasil data extract'
[2024-11-21T07:17:42.160+0000] {taskinstance.py:1225} INFO - Marking task as FAILED. dag_id=etl_pipeline, task_id=transform_google_trends, run_id=manual__2024-11-21T07:17:25.563459+00:00, execution_date=20241121T071725, start_date=20241121T071741, end_date=20241121T071742
[2024-11-21T07:17:42.174+0000] {taskinstance.py:340} INFO - ::group::Post task execution logs
[2024-11-21T07:17:42.175+0000] {standard_task_runner.py:124} ERROR - Failed to execute job 114 for task transform_google_trends ([Errno 2] No such file or directory: '/opt/airflow/dags/etl/dags/hasil data extract'; 101)
Traceback (most recent call last):
  File "/home/airflow/.local/lib/python3.12/site-packages/airflow/task/task_runner/standard_task_runner.py", line 117, in _start_by_fork
    ret = args.func(args, dag=self.dag)
          ^^^^^^^^^^^^^^^^^^^^^^^^^^^^^
  File "/home/airflow/.local/lib/python3.12/site-packages/airflow/cli/cli_config.py", line 49, in command
    return func(*args, **kwargs)
           ^^^^^^^^^^^^^^^^^^^^^
  File "/home/airflow/.local/lib/python3.12/site-packages/airflow/utils/cli.py", line 116, in wrapper
    return f(*args, **kwargs)
           ^^^^^^^^^^^^^^^^^^
  File "/home/airflow/.local/lib/python3.12/site-packages/airflow/cli/commands/task_command.py", line 483, in task_run
    task_return_code = _run_task_by_selected_method(args, _dag, ti)
                       ^^^^^^^^^^^^^^^^^^^^^^^^^^^^^^^^^^^^^^^^^^^^
  File "/home/airflow/.local/lib/python3.12/site-packages/airflow/cli/commands/task_command.py", line 256, in _run_task_by_selected_method
    return _run_raw_task(args, ti)
           ^^^^^^^^^^^^^^^^^^^^^^^
  File "/home/airflow/.local/lib/python3.12/site-packages/airflow/cli/commands/task_command.py", line 341, in _run_raw_task
    return ti._run_raw_task(
           ^^^^^^^^^^^^^^^^^
  File "/home/airflow/.local/lib/python3.12/site-packages/airflow/utils/session.py", line 97, in wrapper
    return func(*args, session=session, **kwargs)
           ^^^^^^^^^^^^^^^^^^^^^^^^^^^^^^^^^^^^^^
  File "/home/airflow/.local/lib/python3.12/site-packages/airflow/models/taskinstance.py", line 3005, in _run_raw_task
    return _run_raw_task(
           ^^^^^^^^^^^^^^
  File "/home/airflow/.local/lib/python3.12/site-packages/airflow/models/taskinstance.py", line 273, in _run_raw_task
    TaskInstance._execute_task_with_callbacks(
  File "/home/airflow/.local/lib/python3.12/site-packages/airflow/models/taskinstance.py", line 3159, in _execute_task_with_callbacks
    result = self._execute_task(context, task_orig)
             ^^^^^^^^^^^^^^^^^^^^^^^^^^^^^^^^^^^^^^
  File "/home/airflow/.local/lib/python3.12/site-packages/airflow/models/taskinstance.py", line 3183, in _execute_task
    return _execute_task(self, context, task_orig)
           ^^^^^^^^^^^^^^^^^^^^^^^^^^^^^^^^^^^^^^^
  File "/home/airflow/.local/lib/python3.12/site-packages/airflow/models/taskinstance.py", line 767, in _execute_task
    result = _execute_callable(context=context, **execute_callable_kwargs)
             ^^^^^^^^^^^^^^^^^^^^^^^^^^^^^^^^^^^^^^^^^^^^^^^^^^^^^^^^^^^^^
  File "/home/airflow/.local/lib/python3.12/site-packages/airflow/models/taskinstance.py", line 733, in _execute_callable
    return ExecutionCallableRunner(
           ^^^^^^^^^^^^^^^^^^^^^^^^
  File "/home/airflow/.local/lib/python3.12/site-packages/airflow/utils/operator_helpers.py", line 252, in run
    return self.func(*args, **kwargs)
           ^^^^^^^^^^^^^^^^^^^^^^^^^^
  File "/home/airflow/.local/lib/python3.12/site-packages/airflow/models/baseoperator.py", line 417, in wrapper
    return func(self, *args, **kwargs)
           ^^^^^^^^^^^^^^^^^^^^^^^^^^^
  File "/home/airflow/.local/lib/python3.12/site-packages/airflow/operators/python.py", line 238, in execute
    return_value = self.execute_callable()
                   ^^^^^^^^^^^^^^^^^^^^^^^
  File "/home/airflow/.local/lib/python3.12/site-packages/airflow/operators/python.py", line 256, in execute_callable
    return runner.run(*self.op_args, **self.op_kwargs)
           ^^^^^^^^^^^^^^^^^^^^^^^^^^^^^^^^^^^^^^^^^^^
  File "/home/airflow/.local/lib/python3.12/site-packages/airflow/utils/operator_helpers.py", line 252, in run
    return self.func(*args, **kwargs)
           ^^^^^^^^^^^^^^^^^^^^^^^^^^
  File "/opt/airflow/dags/etl/transform_google_trends.py", line 46, in process_all_files
    for file_name in os.listdir(DATA_FOLDER):
                     ^^^^^^^^^^^^^^^^^^^^^^^
FileNotFoundError: [Errno 2] No such file or directory: '/opt/airflow/dags/etl/dags/hasil data extract'
[2024-11-21T07:17:42.209+0000] {local_task_job_runner.py:266} INFO - Task exited with return code 1
[2024-11-21T07:17:42.226+0000] {taskinstance.py:3895} INFO - 0 downstream tasks scheduled from follow-on schedule check
[2024-11-21T07:17:42.233+0000] {local_task_job_runner.py:245} INFO - ::endgroup::
