[2024-11-21T08:27:13.431+0000] {local_task_job_runner.py:123} INFO - ::group::Pre task execution logs
[2024-11-21T08:27:13.447+0000] {taskinstance.py:2613} INFO - Dependencies all met for dep_context=non-requeueable deps ti=<TaskInstance: etl_pipeline.create_table manual__2024-11-21T08:07:45.849669+00:00 [queued]>
[2024-11-21T08:27:13.455+0000] {taskinstance.py:2613} INFO - Dependencies all met for dep_context=requeueable deps ti=<TaskInstance: etl_pipeline.create_table manual__2024-11-21T08:07:45.849669+00:00 [queued]>
[2024-11-21T08:27:13.457+0000] {taskinstance.py:2866} INFO - Starting attempt 2 of 2
[2024-11-21T08:27:13.471+0000] {taskinstance.py:2889} INFO - Executing <Task(PostgresOperator): create_table> on 2024-11-21 08:07:45.849669+00:00
[2024-11-21T08:27:13.481+0000] {warnings.py:112} WARNING - /home/***/.local/lib/python3.12/site-packages/***/task/task_runner/standard_task_runner.py:70: DeprecationWarning: This process (pid=1167) is multi-threaded, use of fork() may lead to deadlocks in the child.
  pid = os.fork()

[2024-11-21T08:27:13.483+0000] {standard_task_runner.py:72} INFO - Started process 1171 to run task
[2024-11-21T08:27:13.483+0000] {standard_task_runner.py:104} INFO - Running: ['***', 'tasks', 'run', 'etl_pipeline', 'create_table', 'manual__2024-11-21T08:07:45.849669+00:00', '--job-id', '156', '--raw', '--subdir', 'DAGS_FOLDER/dag.py', '--cfg-path', '/tmp/tmp4farpfha']
[2024-11-21T08:27:13.485+0000] {standard_task_runner.py:105} INFO - Job 156: Subtask create_table
[2024-11-21T08:27:13.528+0000] {task_command.py:467} INFO - Running <TaskInstance: etl_pipeline.create_table manual__2024-11-21T08:07:45.849669+00:00 [running]> on host 7a40aa914b11
[2024-11-21T08:27:13.876+0000] {taskinstance.py:3132} INFO - Exporting env vars: AIRFLOW_CTX_DAG_OWNER='***' AIRFLOW_CTX_DAG_ID='etl_pipeline' AIRFLOW_CTX_TASK_ID='create_table' AIRFLOW_CTX_EXECUTION_DATE='2024-11-21T08:07:45.849669+00:00' AIRFLOW_CTX_TRY_NUMBER='2' AIRFLOW_CTX_DAG_RUN_ID='manual__2024-11-21T08:07:45.849669+00:00'
[2024-11-21T08:27:13.878+0000] {logging_mixin.py:190} INFO - Task instance is in running state
[2024-11-21T08:27:13.879+0000] {logging_mixin.py:190} INFO -  Previous state of the Task instance: queued
[2024-11-21T08:27:13.880+0000] {logging_mixin.py:190} INFO - Current task name:create_table state:running start_date:2024-11-21 08:27:13.449101+00:00
[2024-11-21T08:27:13.881+0000] {logging_mixin.py:190} INFO - Dag name:etl_pipeline and current dag run status:running
[2024-11-21T08:27:13.881+0000] {taskinstance.py:731} INFO - ::endgroup::
[2024-11-21T08:27:13.882+0000] {sql.py:278} INFO - Executing: 
        CREATE TABLE IF NOT EXISTS skincare_data (
				    id SERIAL PRIMARY KEY,
				    username TEXT NOT NULL,
				    date TIMESTAMP,
					review_content TEXT,
				    purchase_point TEXT,
				    rating INTEGER,
				    recommend TEXT,
					jenis_produk TEXT,
					trend INTEGER,
				    age_category TEXT,
				    periode_penggunaan TEXT,
				    skintype TEXT,
				    skintone TEXT,
				    undertone TEXT
        );
        
[2024-11-21T08:27:13.892+0000] {base.py:84} INFO - Retrieving connection 'skincare_connection'
[2024-11-21T08:27:13.901+0000] {base.py:84} INFO - Retrieving connection 'skincare_connection'
[2024-11-21T08:27:13.904+0000] {taskinstance.py:3311} ERROR - Task failed with exception
Traceback (most recent call last):
  File "/home/airflow/.local/lib/python3.12/site-packages/airflow/models/taskinstance.py", line 767, in _execute_task
    result = _execute_callable(context=context, **execute_callable_kwargs)
             ^^^^^^^^^^^^^^^^^^^^^^^^^^^^^^^^^^^^^^^^^^^^^^^^^^^^^^^^^^^^^
  File "/home/airflow/.local/lib/python3.12/site-packages/airflow/models/taskinstance.py", line 733, in _execute_callable
    return ExecutionCallableRunner(
           ^^^^^^^^^^^^^^^^^^^^^^^^
  File "/home/airflow/.local/lib/python3.12/site-packages/airflow/utils/operator_helpers.py", line 252, in run
    return self.func(*args, **kwargs)
           ^^^^^^^^^^^^^^^^^^^^^^^^^^
  File "/home/airflow/.local/lib/python3.12/site-packages/airflow/models/baseoperator.py", line 417, in wrapper
    return func(self, *args, **kwargs)
           ^^^^^^^^^^^^^^^^^^^^^^^^^^^
  File "/home/airflow/.local/lib/python3.12/site-packages/airflow/providers/common/sql/operators/sql.py", line 284, in execute
    output = hook.run(
             ^^^^^^^^^
  File "/home/airflow/.local/lib/python3.12/site-packages/airflow/providers/common/sql/hooks/sql.py", line 485, in run
    with self._create_autocommit_connection(autocommit) as conn:
         ^^^^^^^^^^^^^^^^^^^^^^^^^^^^^^^^^^^^^^^^^^^^^^
  File "/usr/local/lib/python3.12/contextlib.py", line 137, in __enter__
    return next(self.gen)
           ^^^^^^^^^^^^^^
  File "/home/airflow/.local/lib/python3.12/site-packages/airflow/providers/common/sql/hooks/sql.py", line 609, in _create_autocommit_connection
    with closing(self.get_conn()) as conn:
                 ^^^^^^^^^^^^^^^
  File "/home/airflow/.local/lib/python3.12/site-packages/airflow/providers/postgres/hooks/postgres.py", line 181, in get_conn
    self.conn = psycopg2.connect(**conn_args)
                ^^^^^^^^^^^^^^^^^^^^^^^^^^^^^
  File "/home/airflow/.local/lib/python3.12/site-packages/psycopg2/__init__.py", line 122, in connect
    conn = _connect(dsn, connection_factory=connection_factory, **kwasync)
           ^^^^^^^^^^^^^^^^^^^^^^^^^^^^^^^^^^^^^^^^^^^^^^^^^^^^^^^^^^^^^^^
psycopg2.OperationalError: connection to server at "172.18.0.4", port 5432 failed: Connection refused
	Is the server running on that host and accepting TCP/IP connections?

[2024-11-21T08:27:13.917+0000] {logging_mixin.py:190} INFO - Task instance in failure state
[2024-11-21T08:27:13.918+0000] {logging_mixin.py:190} INFO - Task start:2024-11-21 08:27:13.449101+00:00 end:2024-11-21 08:27:13.916593+00:00 duration:0.467492
[2024-11-21T08:27:13.919+0000] {logging_mixin.py:190} INFO - Task:<Task(PostgresOperator): create_table> dag:<DAG: etl_pipeline> dagrun:<DagRun etl_pipeline @ 2024-11-21 08:07:45.849669+00:00: manual__2024-11-21T08:07:45.849669+00:00, state:running, queued_at: 2024-11-21 08:23:23.068907+00:00. externally triggered: True>
[2024-11-21T08:27:13.920+0000] {logging_mixin.py:190} INFO - Failure caused by connection to server at "172.18.0.4", port 5432 failed: Connection refused
	Is the server running on that host and accepting TCP/IP connections?
[2024-11-21T08:27:13.920+0000] {taskinstance.py:1225} INFO - Marking task as FAILED. dag_id=etl_pipeline, task_id=create_table, run_id=manual__2024-11-21T08:07:45.849669+00:00, execution_date=20241121T080745, start_date=20241121T082713, end_date=20241121T082713
[2024-11-21T08:27:13.934+0000] {taskinstance.py:340} INFO - ::group::Post task execution logs
[2024-11-21T08:27:13.935+0000] {standard_task_runner.py:124} ERROR - Failed to execute job 156 for task create_table (connection to server at "172.18.0.4", port 5432 failed: Connection refused
	Is the server running on that host and accepting TCP/IP connections?
; 1171)
Traceback (most recent call last):
  File "/home/airflow/.local/lib/python3.12/site-packages/airflow/task/task_runner/standard_task_runner.py", line 117, in _start_by_fork
    ret = args.func(args, dag=self.dag)
          ^^^^^^^^^^^^^^^^^^^^^^^^^^^^^
  File "/home/airflow/.local/lib/python3.12/site-packages/airflow/cli/cli_config.py", line 49, in command
    return func(*args, **kwargs)
           ^^^^^^^^^^^^^^^^^^^^^
  File "/home/airflow/.local/lib/python3.12/site-packages/airflow/utils/cli.py", line 116, in wrapper
    return f(*args, **kwargs)
           ^^^^^^^^^^^^^^^^^^
  File "/home/airflow/.local/lib/python3.12/site-packages/airflow/cli/commands/task_command.py", line 483, in task_run
    task_return_code = _run_task_by_selected_method(args, _dag, ti)
                       ^^^^^^^^^^^^^^^^^^^^^^^^^^^^^^^^^^^^^^^^^^^^
  File "/home/airflow/.local/lib/python3.12/site-packages/airflow/cli/commands/task_command.py", line 256, in _run_task_by_selected_method
    return _run_raw_task(args, ti)
           ^^^^^^^^^^^^^^^^^^^^^^^
  File "/home/airflow/.local/lib/python3.12/site-packages/airflow/cli/commands/task_command.py", line 341, in _run_raw_task
    return ti._run_raw_task(
           ^^^^^^^^^^^^^^^^^
  File "/home/airflow/.local/lib/python3.12/site-packages/airflow/utils/session.py", line 97, in wrapper
    return func(*args, session=session, **kwargs)
           ^^^^^^^^^^^^^^^^^^^^^^^^^^^^^^^^^^^^^^
  File "/home/airflow/.local/lib/python3.12/site-packages/airflow/models/taskinstance.py", line 3005, in _run_raw_task
    return _run_raw_task(
           ^^^^^^^^^^^^^^
  File "/home/airflow/.local/lib/python3.12/site-packages/airflow/models/taskinstance.py", line 273, in _run_raw_task
    TaskInstance._execute_task_with_callbacks(
  File "/home/airflow/.local/lib/python3.12/site-packages/airflow/models/taskinstance.py", line 3159, in _execute_task_with_callbacks
    result = self._execute_task(context, task_orig)
             ^^^^^^^^^^^^^^^^^^^^^^^^^^^^^^^^^^^^^^
  File "/home/airflow/.local/lib/python3.12/site-packages/airflow/models/taskinstance.py", line 3183, in _execute_task
    return _execute_task(self, context, task_orig)
           ^^^^^^^^^^^^^^^^^^^^^^^^^^^^^^^^^^^^^^^
  File "/home/airflow/.local/lib/python3.12/site-packages/airflow/models/taskinstance.py", line 767, in _execute_task
    result = _execute_callable(context=context, **execute_callable_kwargs)
             ^^^^^^^^^^^^^^^^^^^^^^^^^^^^^^^^^^^^^^^^^^^^^^^^^^^^^^^^^^^^^
  File "/home/airflow/.local/lib/python3.12/site-packages/airflow/models/taskinstance.py", line 733, in _execute_callable
    return ExecutionCallableRunner(
           ^^^^^^^^^^^^^^^^^^^^^^^^
  File "/home/airflow/.local/lib/python3.12/site-packages/airflow/utils/operator_helpers.py", line 252, in run
    return self.func(*args, **kwargs)
           ^^^^^^^^^^^^^^^^^^^^^^^^^^
  File "/home/airflow/.local/lib/python3.12/site-packages/airflow/models/baseoperator.py", line 417, in wrapper
    return func(self, *args, **kwargs)
           ^^^^^^^^^^^^^^^^^^^^^^^^^^^
  File "/home/airflow/.local/lib/python3.12/site-packages/airflow/providers/common/sql/operators/sql.py", line 284, in execute
    output = hook.run(
             ^^^^^^^^^
  File "/home/airflow/.local/lib/python3.12/site-packages/airflow/providers/common/sql/hooks/sql.py", line 485, in run
    with self._create_autocommit_connection(autocommit) as conn:
         ^^^^^^^^^^^^^^^^^^^^^^^^^^^^^^^^^^^^^^^^^^^^^^
  File "/usr/local/lib/python3.12/contextlib.py", line 137, in __enter__
    return next(self.gen)
           ^^^^^^^^^^^^^^
  File "/home/airflow/.local/lib/python3.12/site-packages/airflow/providers/common/sql/hooks/sql.py", line 609, in _create_autocommit_connection
    with closing(self.get_conn()) as conn:
                 ^^^^^^^^^^^^^^^
  File "/home/airflow/.local/lib/python3.12/site-packages/airflow/providers/postgres/hooks/postgres.py", line 181, in get_conn
    self.conn = psycopg2.connect(**conn_args)
                ^^^^^^^^^^^^^^^^^^^^^^^^^^^^^
  File "/home/airflow/.local/lib/python3.12/site-packages/psycopg2/__init__.py", line 122, in connect
    conn = _connect(dsn, connection_factory=connection_factory, **kwasync)
           ^^^^^^^^^^^^^^^^^^^^^^^^^^^^^^^^^^^^^^^^^^^^^^^^^^^^^^^^^^^^^^^
psycopg2.OperationalError: connection to server at "172.18.0.4", port 5432 failed: Connection refused
	Is the server running on that host and accepting TCP/IP connections?

[2024-11-21T08:27:13.981+0000] {local_task_job_runner.py:266} INFO - Task exited with return code 1
[2024-11-21T08:27:14.001+0000] {taskinstance.py:3895} INFO - 0 downstream tasks scheduled from follow-on schedule check
[2024-11-21T08:27:14.008+0000] {local_task_job_runner.py:245} INFO - ::endgroup::
